Workbook

Sheet Summary
A1: PROTOPUS — Baker + Mixer: BOM, cost breakup and final cost
A2: PROTOPUS, Delhi · 29 Sep 2026 · All figures are live formulas; edit the blue cells on the Inputs sheet.
B4: Prototype (India) | C4: Production unit (China parts) | D4: Deck hardware target | E4: Headroom vs target | F4: Prototype → production saving
A5: Baker | B5: ='Baker Final Cost'!B10 -> 373417.94 | C5: ='Baker Final Cost'!B17 -> 144842.3 | D5: ='Baker Final Cost'!B18 -> 150000 | E5: =D5-C5 -> 5157.6984 | F5: =B5-C5 -> 228575.64
A6: Mixer | B6: ='Mixer Final Cost'!B10 -> 74846.931 | C6: ='Mixer Final Cost'!B17 -> 13740.256 | D6: ='Mixer Final Cost'!B18 -> 15000 | E6: =D6-C6 -> 1259.744 | F6: =B6-C6 -> 61106.675
A7: Both | B7: =SUM(B5:B6) -> 448264.88 | C7: =SUM(C5:C6) -> 158582.56 | D7: =SUM(D5:D6) -> 165000 | E7: =SUM(E5:E6) -> 6417.4424 | F7: =SUM(F5:F6) -> 289682.32
A9: Where the prototype money goes
A10: Baker section | B10: All-in ₹ | C10: % of Baker | E10: Mixer section | F10: All-in ₹ | G10: % of Mixer
A11: ='Baker Cost Breakup'!B5 -> Frame & enclosure | B11: ='Baker Cost Breakup'!J5 -> 28303.598 | C11: ='Baker Cost Breakup'!K5 -> 0.07579603 | E11: ='Mixer Cost Breakup'!B5 -> Capture and generation | F11: ='Mixer Cost Breakup'!J5 -> 22783.938 | G11: ='Mixer Cost Breakup'!K5 -> 0.30440711
A12: ='Baker Cost Breakup'!B6 -> Motion | B12: ='Baker Cost Breakup'!J6 -> 98460.268 | C12: ='Baker Cost Breakup'!K6 -> 0.2636731 | E12: ='Mixer Cost Breakup'!B6 -> Front end and instruments | F12: ='Mixer Cost Breakup'!J6 -> 19561.693 | G12: ='Mixer Cost Breakup'!K6 -> 0.26135598
A13: ='Baker Cost Breakup'!B7 -> Zone A: mill, drill, laser | B13: ='Baker Cost Breakup'!J7 -> 47906.268 | C13: ='Baker Cost Breakup'!K7 -> 0.12829128 | E13: ='Mixer Cost Breakup'!B7 -> Host, screen, I/O | F13: ='Mixer Cost Breakup'!J7 -> 30764.8 | G13: ='Mixer Cost Breakup'!K7 -> 0.41103622
A14: ='Baker Cost Breakup'!B8 -> Zone B: mask, UV, wipe | B14: ='Baker Cost Breakup'!J8 -> 40024.122 | C14: ='Baker Cost Breakup'!K8 -> 0.10718318 | E14: ='Mixer Cost Breakup'!B8 -> Enclosure | F14: ='Mixer Cost Breakup'!J8 -> 1736.5 | G14: ='Mixer Cost Breakup'!K8 -> 0.023200684
A15: ='Baker Cost Breakup'!B9 -> Stencil film | B15: ='Baker Cost Breakup'!J9 -> 6675.75 | C15: ='Baker Cost Breakup'!K9 -> 0.017877422
A16: ='Baker Cost Breakup'!B10 -> Placement + reflow | B16: ='Baker Cost Breakup'!J10 -> 5695.49 | C16: ='Baker Cost Breakup'!K10 -> 0.01525232
A17: ='Baker Cost Breakup'!B11 -> Board handling | B17: ='Baker Cost Breakup'!J11 -> 345 | C17: ='Baker Cost Breakup'!K11 -> 0.00092389775
A18: ='Baker Cost Breakup'!B12 -> Electronics & control | B18: ='Baker Cost Breakup'!J12 -> 49432.75 | C18: ='Baker Cost Breakup'!K12 -> 0.13237915
A19: ='Baker Cost Breakup'!B13 -> Resin printer (high-temp jigs) | B19: ='Baker Cost Breakup'!J13 -> 89352.7 | C19: ='Baker Cost Breakup'!K13 -> 0.23928336
A20: ='Baker Cost Breakup'!B14 -> First-run consumables | B20: ='Baker Cost Breakup'!J14 -> 7222 | C20: ='Baker Cost Breakup'!K14 -> 0.01934026
A24: Notes and open items
A25: 1. Numbers reconcile with PROTOPUS Cost Report (29 Sep 2026): Baker ₹3,73,418 / Mixer ₹74,847 prototype; ₹1,44,842 / ₹13,740 production.
A26: 2. Production unit figures carry no contingency in the source report. The "risk-adjusted" line on each Final Cost sheet adds an optional allowance (Inputs).
A27: 3. Production cost assumes China parts + assembly/QC in Delhi. A China turnkey (fully assembled) quote must be compared on landed-Delhi cost; see the China plan PDF.
A28: 4. Board size mismatch to freeze before tooling: workflow story says 100 × 160 mm, BOM buys 100 × 150 mm FR4.
A29: 5. The 10.1-inch 405 nm UV light board (Baker prototype) is an estimate: its AliExpress price could not be read.
A30: 6. Spindle and laser are retail prices; factory quotes at 100 units should be lower. Confirm duty and freight with a customs broker before ordering.
A31: 7. Jig printing on Baker’s own UV engine (production) replaces the separate resin printer and is flagged for testing.

Sheet PoC Budget
A1: PROTOPUS — proof-of-concept budget (the ask)
A2: Blue = inputs you can change. The total rounds to the nearest lakh; the reserve is whatever the rounding leaves. Hardware lines link to the cost sheets.
A4: Inputs
A5: Input | B5: Value | C5: Note
A6: Runway (months) | B6: 9 | C6: 6 months to proof of concept (deck timeline) + 3 months to close the next round
A7: Engineers (software + firmware) | B7: 1 | C7: One software engineer who also writes the firmware; the founder covers mechanical and electronics
A8: Cost per engineer per month | B8: 50000 | C8: ASSUMPTION: software + firmware in one person, Delhi; ₹40,000 would lower the ask to ₹15L. The ₹10L ask assumed ₹25,000
A9: Founder stipend per month | B9: 0 | C9: Deducted: the founder takes no stipend during the proof of concept
A10: Proto software + compute per month | B10: 15000 | C10: ASSUMPTION: LLM API usage + hosting; the ₹10L ask had ₹1,00,000 over 6 months
A11: Reserve on lines without built-in contingency | B11: 0.08 | C11: Hardware builds already carry 15% contingency, so the reserve applies to the other lines only
A13: Budget lines
A14: Line | B14: Amount ₹ | C14: Group | D14: Basis | E14: Has own contingency?
A15: Baker prototype build | B15: ='Baker Final Cost'!B10 -> 373417.94 | C15: Hardware | D15: Costed BOM, 70 lines, incl. duty + 15% contingency | E15: Y
A16: Mixer prototype build | B16: ='Mixer Final Cost'!B10 -> 74846.931 | C16: Hardware | D16: Costed BOM, 26 lines, incl. duty + 15% contingency | E16: Y
A17: Baker Rev B iteration (heads, fixture, film module, wiring) | B17: 100000 | C17: Iteration + PoC build-out | D17: ASSUMPTION ≈ 32% of Baker parts: one partial rebuild after the 4 open process points are tested | E17: N
A18: Mixer production board Rev A, 5 units (8-bit design) | B18: 60000 | C18: Iteration + PoC build-out | D18: ASSUMPTION: 5 × ~₹9,900 parts (cost report) + small-batch PCBA, stencil, courier. Units double as maker-studio demo units | E18: N
A19: PoC consumables (~150 test boards) | B19: 60000 | C19: Iteration + PoC build-out | D19: ASSUMPTION: FR4 ₹99/board (BOM), bits/drills, TR300 resin, mask, paste, demo components | E19: N
A20: Engineers | B20: =$B$7*$B$8*$B$6 -> 450000 | C20: People | D20: Engineers × monthly cost × runway | E20: N
A21: Founder stipend | B21: =$B$9*$B$6 -> 0 | C21: People | D21: Stipend × runway | E21: N
A22: Proto software + compute | B22: =$B$10*$B$6 -> 135000 | C22: Software | D22: Monthly × runway | E22: N
A23: Testing + tooling | B23: 100000 | C23: Lab + tooling | D23: From the ₹10L ask: reference instruments, laser power meter, dial indicator, hand tools | E23: N
A24: Lab set-up + safety | B24: 50000 | C24: Lab + tooling | D24: ASSUMPTION: ESD benches, fume extraction, fire safety, storage (university lab, no rent) | E24: N
A25: IP + legal | B25: 75000 | C25: IP, outreach + reserve | D25: ASSUMPTION: trademark filings, provisional patent drafting, founder/employee agreements | E25: N
A26: Demos, travel, maker-studio outreach | B26: 50000 | C26: IP, outreach + reserve | D26: ASSUMPTION: studio visits, demo videos, events | E26: N
A27: Subtotal | B27: =SUM(B15:B26) -> 1528264.9
A28: Lines without built-in contingency | B28: =SUMIF(E15:E26,"N",B15:B26) -> 1080000
A29: THE ASK (rounded to nearest lakh) | B29: =ROUND((B27+B28*$B$11)/100000,0)*100000 -> 1600000
A30: Reserve (ask − subtotal) | B30: =B29-B27 -> 71735.124 | C30: =IF(B28=0,0,B30/B28) -> 0.066421411 | D30: Reserve as % of lines without built-in contingency
A32: By group (for the ask slide)
A33: Group | B33: Amount ₹ | C33: % of ask
A34: Hardware | B34: =SUMIF($C$15:$C$26,A34,$B$15:$B$26) -> 448264.88 | C34: =IF($B$29=0,0,B34/$B$29) -> 0.28016555
A35: Iteration + PoC build-out | B35: =SUMIF($C$15:$C$26,A35,$B$15:$B$26) -> 220000 | C35: =IF($B$29=0,0,B35/$B$29) -> 0.1375
A36: People | B36: =SUMIF($C$15:$C$26,A36,$B$15:$B$26) -> 450000 | C36: =IF($B$29=0,0,B36/$B$29) -> 0.28125
A37: Software | B37: =SUMIF($C$15:$C$26,A37,$B$15:$B$26) -> 135000 | C37: =IF($B$29=0,0,B37/$B$29) -> 0.084375
A38: Lab + tooling | B38: =SUMIF($C$15:$C$26,A38,$B$15:$B$26) -> 150000 | C38: =IF($B$29=0,0,B38/$B$29) -> 0.09375
A39: IP, outreach + reserve | B39: =SUMIF($C$15:$C$26,A39,$B$15:$B$26)+B30 -> 196735.12 | C39: =IF($B$29=0,0,B39/$B$29) -> 0.12295945
A40: Check: groups = ask | B40: =IF(ABS(SUM(B34:B39)-B29)<1,"OK","MISMATCH") -> OK
A42: Finding the sweet point: three ways to fund the proof of concept
A43: Option | B43: Ask ₹ | C43: Runway | D43: What it buys / why not
A44: Lean (the old ask) | B44: 1000000 | C44: 6 months | D44: One build, engineers at ₹25,000/month, no iteration money, no reserve. Runway ends exactly at PoC: no time to raise, and one failed process point stops the project.
...

Sheet Baker BOM
A1: Baker — prototype bill of materials (India-sourced)
A2: One prototype unit. Blue = inputs (qty, price, currency). Unit ₹ converts USD at the Inputs rate. Source column names the listing the price was read from.
A4: # | B4: Code | C4: Section | D4: Part / description | E4: Qty | F4: Unit price | G4: Cur | H4: Unit ₹ | I4: Line ₹ | J4: Imported? | K4: Price basis | L4: Source (listing seen)
A5: 1 | B5: A | C5: Frame & enclosure | D5: 20x40 T-slot extrusion, 1000 mm | E5: 8 | F5: 949 | G5: INR | H5: =IF(G5="USD",F5*Inputs!$B$5,F5) -> 949 | I5: =E5*H5 -> 7592 | J5: =IF(G5="USD","Yes","No") -> No | K5: Listing | L5: robu.in
A6: 2 | B6: A | C6: Frame & enclosure | D6: Brackets, T-nuts, fasteners | E6: 1 | F6: 2500 | G6: INR | H6: =IF(G6="USD",F6*Inputs!$B$5,F6) -> 2500 | I6: =E6*H6 -> 2500 | J6: =IF(G6="USD","Yes","No") -> No | K6: Estimate
A7: 3 | B7: A | C7: Frame & enclosure | D7: 6061 aluminium plate 6 mm (base + shuttle fixture), kg | E7: 3 | F7: 375 | G7: INR | H7: =IF(G7="USD",F7*Inputs!$B$5,F7) -> 375 | I7: =E7*H7 -> 1125 | J7: =IF(G7="USD","Yes","No") -> No | K7: Listing | L7: www.indiamart.com
A8: 4 | B8: A | C8: Frame & enclosure | D8: 3 mm clear acrylic panel, 24x24 in (laser-cut in-house) | E8: 4 | F8: 900 | G8: INR | H8: =IF(G8="USD",F8*Inputs!$B$5,F8) -> 900 | I8: =E8*H8 -> 3600 | J8: =IF(G8="USD","Yes","No") -> No | K8: Estimate | L8: www.acrylicsheetsindia.com
A9: 5 | B9: A | C9: Frame & enclosure | D9: Orange laser-safe viewing window (450 nm) | E9: 1 | F9: 2500 | G9: INR | H9: =IF(G9="USD",F9*Inputs!$B$5,F9) -> 2500 | I9: =E9*H9 -> 2500 | J9: =IF(G9="USD","Yes","No") -> No | K9: Estimate | L9: phillips-safety.com
A10: 6 | B10: A | C10: Frame & enclosure | D10: MC-38 door interlock switch | E10: 2 | F10: 44 | G10: INR | H10: =IF(G10="USD",F10*Inputs!$B$5,F10) -> 44 | I10: =E10*H10 -> 88 | J10: =IF(G10="USD","Yes","No") -> No | K10: Listing | L10: robu.in
A11: 7 | B11: A | C11: Frame & enclosure | D11: Emergency stop, mushroom head | E11: 1 | F11: 200 | G11: INR | H11: =IF(G11="USD",F11*Inputs!$B$5,F11) -> 200 | I11: =E11*H11 -> 200 | J11: =IF(G11="USD","Yes","No") -> No | K11: Listing | L11: robu.in
A12: 8 | B12: A | C12: Frame & enclosure | D12: Laser safety goggles OD6+ 190-490 nm | E12: 2 | F12: 29.49 | G12: USD | H12: =IF(G12="USD",F12*Inputs!$B$5,F12) -> 2595.12 | I12: =E12*H12 -> 5190.24 | J12: =IF(G12="USD","Yes","No") -> Yes | K12: Listing | L12: woodartsupply.com
A13: 9 | B13: B | C13: Motion | D13: Ball-screw linear stage, 200-300 mm (shuttle X, two cross axes) | E13: 3 | F13: 15000 | G13: INR | H13: =IF(G13="USD",F13*Inputs!$B$5,F13) -> 15000 | I13: =E13*H13 -> 45000 | J13: =IF(G13="USD","Yes","No") -> No | K13: Listing | L13: www.indiamart.com
A14: 10 | B14: B | C14: Motion | D14: NEMA23 stepper 18.9 kg-cm (if stage ships without motor) | E14: 3 | F14: 1529 | G14: INR | H14: =IF(G14="USD",F14*Inputs!$B$5,F14) -> 1529 | I14: =E14*H14 -> 4587 | J14: =IF(G14="USD","Yes","No") -> No | K14: Listing | L14: robu.in
A15: 11 | B15: B | C15: Motion | D15: 100 mm SFU1605 stage + NEMA17 (two Z axes) | E15: 2 | F15: 84.99 | G15: USD | H15: =IF(G15="USD",F15*Inputs!$B$5,F15) -> 7479.12 | I15: =E15*H15 -> 14958.24 | J15: =IF(G15="USD","Yes","No") -> Yes | K15: Listing | L15: www.sainsmart.com
A16: 12 | B16: B | C16: Motion | D16: DM556 digital stepper driver (NEMA23 axes) | E16: 3 | F16: 847 | G16: INR | H16: =IF(G16="USD",F16*Inputs!$B$5,F16) -> 847 | I16: =E16*H16 -> 2541 | J16: =IF(G16="USD","Yes","No") -> No | K16: Listing | L16: probots.co.in
A17: 13 | B17: B | C17: Motion | D17: NEMA17 stepper 7.2 kg-cm (film, syringes, ejector, stencil lift) | E17: 6 | F17: 980 | G17: INR | H17: =IF(G17="USD",F17*Inputs!$B$5,F17) -> 980 | I17: =E17*H17 -> 5880 | J17: =IF(G17="USD","Yes","No") -> No | K17: Listing | L17: robu.in
A18: 14 | B18: B | C18: Motion | D18: TMC2209 driver | E18: 8 | F18: 619 | G18: INR | H18: =IF(G18="USD",F18*Inputs!$B$5,F18) -> 619 | I18: =E18*H18 -> 4952 | J18: =IF(G18="USD","Yes","No") -> No | K18: Listing | L18: robu.in
... A29: 25 | B29: C | C29: Zone A: mill, drill, laser | D29: Wet/dry vacuum 1000 W (dust extraction) | E29: 1 | F29: 3786 | G29: INR | H29: =IF(G29="USD",F29*Inputs!$B$5,F29) -> 3786 | I29: =E29*H29 -> 3786 | J29: =IF(G29="USD","Yes","No") -> No | K29: Listing | L29: www.indiamart.com
A30: 26 | B30: C | C30: Zone A: mill, drill, laser | D30: Z touch probe (pogo pin + clip) | E30: 1 | F30: 300 | G30: INR | H30: =IF(G30="USD",F30*Inputs!$B$5,F30) -> 300 | I30: =E30*H30 -> 300 | J30: =IF(G30="USD","Yes","No") -> No | K30: Estimate
A31: 27 | B31: D | C31: Zone B: mask, UV, wipe | D31: 30 cc syringe barrel with piston | E31: 10 | F31: 50 | G31: INR | H31: =IF(G31="USD",F31*Inputs!$B$5,F31) -> 50 | I31: =E31*H31 -> 500 | J31: =IF(G31="USD","Yes","No") -> No | K31: Listing | L31: www.indiamart.com
A32: 28 | B32: D | C32: Zone B: mask, UV, wipe | D32: Blunt dispensing needle | E32: 20 | F32: 11.5 | G32: INR | H32: =IF(G32="USD",F32*Inputs!$B$5,F32) -> 11.5 | I32: =E32*H32 -> 230 | J32: =IF(G32="USD","Yes","No") -> No | K32: Listing | L32: www.indiamart.com
A33: 29 | B33: D | C33: Zone B: mask, UV, wipe | D33: 10.1 in 12K mono LCD (Saturn 3 Ultra part, doubles as printer spare) | E33: 1 | F33: 14999 | G33: INR | H33: =IF(G33="USD",F33*Inputs!$B$5,F33) -> 14999 | I33: =E33*H33 -> 14999 | J33: =IF(G33="USD","Yes","No") -> No | K33: Listing | L33: diy3d.in
A34: 30 | B34: D | C34: Zone B: mask, UV, wipe | D34: ChiTu L K1 board (drives 10.1 in LCD) | E34: 1 | F34: 56.68 | G34: USD | H34: =IF(G34="USD",F34*Inputs!$B$5,F34) -> 4987.84 | I34: =E34*H34 -> 4987.84 | J34: =IF(G34="USD","Yes","No") -> Yes | K34: Listing | L34: www.chitusystems.com
A35: 31 | B35: D | C35: Zone B: mask, UV, wipe | D35: 405 nm parallel UV light board, 10.1 in | E35: 1 | F35: 8000 | G35: INR | H35: =IF(G35="USD",F35*Inputs!$B$5,F35) -> 8000 | I35: =E35*H35 -> 8000 | J35: =IF(G35="USD","Yes","No") -> No | K35: Estimate | L35: www.aliexpress.com
A36: 32 | B36: D | C36: Zone B: mask, UV, wipe | D36: 12 V peristaltic pump (developer) | E36: 1 | F36: 659 | G36: INR | H36: =IF(G36="USD",F36*Inputs!$B$5,F36) -> 659 | I36: =E36*H36 -> 659 | J36: =IF(G36="USD","Yes","No") -> No | K36: Listing | L36: robu.in
A37: 33 | B37: D | C37: Zone B: mask, UV, wipe | D37: Squeegee blade (wiper + paste) | E37: 2 | F37: 1500 | G37: INR | H37: =IF(G37="USD",F37*Inputs!$B$5,F37) -> 1500 | I37: =E37*H37 -> 3000 | J37: =IF(G37="USD","Yes","No") -> No | K37: Listing | L37: www.indiamart.com
A38: 34 | B38: D | C38: Zone B: mask, UV, wipe | D38: 5015 blower (air knife) | E38: 2 | F38: 91 | G38: INR | H38: =IF(G38="USD",F38*Inputs!$B$5,F38) -> 91 | I38: =E38*H38 -> 182 | J38: =IF(G38="USD","Yes","No") -> No | K38: Listing | L38: robu.in
A39: 35 | B39: D | C39: Zone B: mask, UV, wipe | D39: Waste tray and container | E39: 1 | F39: 500 | G39: INR | H39: =IF(G39="USD",F39*Inputs!$B$5,F39) -> 500 | I39: =E39*H39 -> 500 | J39: =IF(G39="USD","Yes","No") -> No | K39: Estimate
A40: 36 | B40: E | C40: Stencil film | D40: Polyimide (Kapton) film roll | E40: 1 | F40: 3150 | G40: INR | H40: =IF(G40="USD",F40*Inputs!$B$5,F40) -> 3150 | I40: =E40*H40 -> 3150 | J40: =IF(G40="USD","Yes","No") -> No | K40: Listing | L40: www.indiamart.com
A41: 37 | B41: E | C41: Stencil film | D41: 12 V holding electromagnet 8 kg | E41: 4 | F41: 259 | G41: INR | H41: =IF(G41="USD",F41*Inputs!$B$5,F41) -> 259 | I41: =E41*H41 -> 1036 | J41: =IF(G41="USD","Yes","No") -> No | K41: Listing | L41: robu.in
A42: 38 | B42: E | C42: Stencil film | D42: Ferrous clamp frame (magnetic 430 shim, not 304) | E42: 1 | F42: 300 | G42: INR | H42: =IF(G42="USD",F42*Inputs!$B$5,F42) -> 300 | I42: =E42*H42 -> 300 | J42: =IF(G42="USD","Yes","No") -> No | K42: Listing | L42: www.indiamart.com
A43: 39 | B43: E | C43: Stencil film | D43: 12 V push-pull solenoid 25 N (film cut-off) | E43: 1 | F43: 819 | G43: INR | H43: =IF(G43="USD",F43*Inputs!$B$5,F43) -> 819 | I43: =E43*H43 -> 819 | J43: =IF(G43="USD","Yes","No") -> No | K43: Listing | L43: robu.in
A44: 40 | B44: E | C44: Stencil film | D44: Roller shafts and spacers | E44: 1 | F44: 500 | G44: INR | H44: =IF(G44="USD",F44*Inputs!$B$5,F44) -> 500 | I44: =E44*H44 -> 500 | J44: =IF(G44="USD","Yes","No") -> No | K44: Estimate
A45: 41 | B45: F | C45: Placement + reflow | D45: 12 V vacuum pump | E45: 1 | F45: 1500 | G45: INR | H45: =IF(G45="USD",F45*Inputs!$B$5,F45) -> 1500 | I45: =E45*H45 -> 1500 | J45: =IF(G45="USD","Yes","No") -> No | K45: Listing | L45: www.indiamart.com
A46: 42 | B46: F | C46: Placement + reflow | D46: 12 V solenoid valve 1/8 in, NC | E46: 1 | F46: 748 | G46: INR | H46: =IF(G46="USD",F46*Inputs!$B$5,F46) -> 748 | I46: =E46*H46 -> 748 | J46: =IF(G46="USD","Yes","No") -> No | K46: Listing | L46: robu.in
A47: 43 | B47: F | C47: Placement + reflow | D47: Foot pedal switch, momentary | E47: 1 | F47: 349 | G47: INR | H47: =IF(G47="USD",F47*Inputs!$B$5,F47) -> 349 | I47: =E47*H47 -> 349 | J47: =IF(G47="USD","Yes","No") -> No | K47: Listing | L47: www.indiamart.com
A48: 44 | B48: F | C48: Placement + reflow | D48: Manual vacuum pen FFQ939 (backup) | E48: 1 | F48: 249 | G48: INR | H48: =IF(G48="USD",F48*Inputs!$B$5,F48) -> 249 | I48: =E48*H48 -> 249 | J48: =IF(G48="USD","Yes","No") -> No | K48: Listing | L48: probots.co.in
A49: 45 | B49: F | C49: Placement + reflow | D49: Silicone heater pad 300 W 230 V (hotplate) | E49: 1 | F49: 850 | G49: INR | H49: =IF(G49="USD",F49*Inputs!$B$5,F49) -> 850 | I49: =E49*H49 -> 850 | J49: =IF(G49="USD","Yes","No") -> No | K49: Listing | L49: www.indiamart.com
A50: 46 | B50: F | C50: Placement + reflow | D50: SSR-25DA solid state relay | E50: 1 | F50: 268 | G50: INR | H50: =IF(G50="USD",F50*Inputs!$B$5,F50) -> 268 | I50: =E50*H50 -> 268 | J50: =IF(G50="USD","Yes","No") -> No | K50: Listing | L50: robu.in
A51: 47 | B51: F | C51: Placement + reflow | D51: MAX31855 thermocouple module | E51: 1 | F51: 569 | G51: INR | H51: =IF(G51="USD",F51*Inputs!$B$5,F51) -> 569 | I51: =E51*H51 -> 569 | J51: =IF(G51="USD","Yes","No") -> No | K51: Listing | L51: robu.in
...

Sheet Baker Cost Breakup
A1: Baker — prototype cost breakup by section
A2: Section totals from the Baker BOM, then duty/courier and contingency.
A4: Code | B4: Section | C4: BOM lines | D4: Listing-priced | E4: Parts ₹ | F4: of which imported ₹ | G4: Duty + courier ₹ | H4: Subtotal ₹ | I4: Contingency ₹ | J4: All-in section cost ₹ | K4: % of total
A5: A | B5: Frame & enclosure | C5: =COUNTIF('Baker BOM'!$B$5:$B$74,A5) -> 8 | D5: =COUNTIFS('Baker BOM'!$B$5:$B$74,A5,'Baker BOM'!$K$5:$K$74,"Listing") -> 5 | E5: =SUMIF('Baker BOM'!$B$5:$B$74,A5,'Baker BOM'!$I$5:$I$74) -> 22795.24 | F5: =SUMIFS('Baker BOM'!$I$5:$I$74,'Baker BOM'!$B$5:$B$74,A5,'Baker BOM'!$G$5:$G$74,"USD") -> 5190.24 | G5: =F5*Inputs!$B$6 -> 1816.584 | H5: =E5+G5 -> 24611.824 | I5: =H5*Inputs!$B$7 -> 3691.7736 | J5: =H5+I5 -> 28303.598 | K5: =IF($J$15=0,0,J5/$J$15) -> 0.07579603
A6: B | B6: Motion | C6: =COUNTIF('Baker BOM'!$B$5:$B$74,A6) -> 10 | D6: =COUNTIFS('Baker BOM'!$B$5:$B$74,A6,'Baker BOM'!$K$5:$K$74,"Listing") -> 10 | E6: =SUMIF('Baker BOM'!$B$5:$B$74,A6,'Baker BOM'!$I$5:$I$74) -> 80382.24 | F6: =SUMIFS('Baker BOM'!$I$5:$I$74,'Baker BOM'!$B$5:$B$74,A6,'Baker BOM'!$G$5:$G$74,"USD") -> 14958.24 | G6: =F6*Inputs!$B$6 -> 5235.384 | H6: =E6+G6 -> 85617.624 | I6: =H6*Inputs!$B$7 -> 12842.644 | J6: =H6+I6 -> 98460.268 | K6: =IF($J$15=0,0,J6/$J$15) -> 0.2636731
A7: C | B7: Zone A: mill, drill, laser | C7: =COUNTIF('Baker BOM'!$B$5:$B$74,A7) -> 8 | D7: =COUNTIFS('Baker BOM'!$B$5:$B$74,A7,'Baker BOM'!$K$5:$K$74,"Listing") -> 6 | E7: =SUMIF('Baker BOM'!$B$5:$B$74,A7,'Baker BOM'!$I$5:$I$74) -> 38270.24 | F7: =SUMIFS('Baker BOM'!$I$5:$I$74,'Baker BOM'!$B$5:$B$74,A7,'Baker BOM'!$G$5:$G$74,"USD") -> 9678.24 | G7: =F7*Inputs!$B$6 -> 3387.384 | H7: =E7+G7 -> 41657.624 | I7: =H7*Inputs!$B$7 -> 6248.6436 | J7: =H7+I7 -> 47906.268 | K7: =IF($J$15=0,0,J7/$J$15) -> 0.12829128
A8: D | B8: Zone B: mask, UV, wipe | C8: =COUNTIF('Baker BOM'!$B$5:$B$74,A8) -> 9 | D8: =COUNTIFS('Baker BOM'!$B$5:$B$74,A8,'Baker BOM'!$K$5:$K$74,"Listing") -> 7 | E8: =SUMIF('Baker BOM'!$B$5:$B$74,A8,'Baker BOM'!$I$5:$I$74) -> 33057.84 | F8: =SUMIFS('Baker BOM'!$I$5:$I$74,'Baker BOM'!$B$5:$B$74,A8,'Baker BOM'!$G$5:$G$74,"USD") -> 4987.84 | G8: =F8*Inputs!$B$6 -> 1745.744 | H8: =E8+G8 -> 34803.584 | I8: =H8*Inputs!$B$7 -> 5220.5376 | J8: =H8+I8 -> 40024.122 | K8: =IF($J$15=0,0,J8/$J$15) -> 0.10718318
A9: E | B9: Stencil film | C9: =COUNTIF('Baker BOM'!$B$5:$B$74,A9) -> 5 | D9: =COUNTIFS('Baker BOM'!$B$5:$B$74,A9,'Baker BOM'!$K$5:$K$74,"Listing") -> 4 | E9: =SUMIF('Baker BOM'!$B$5:$B$74,A9,'Baker BOM'!$I$5:$I$74) -> 5805 | F9: =SUMIFS('Baker BOM'!$I$5:$I$74,'Baker BOM'!$B$5:$B$74,A9,'Baker BOM'!$G$5:$G$74,"USD") -> 0 | G9: =F9*Inputs!$B$6 -> 0 | H9: =E9+G9 -> 5805 | I9: =H9*Inputs!$B$7 -> 870.75 | J9: =H9+I9 -> 6675.75 | K9: =IF($J$15=0,0,J9/$J$15) -> 0.017877422
A10: F | B10: Placement + reflow | C10: =COUNTIF('Baker BOM'!$B$5:$B$74,A10) -> 9 | D10: =COUNTIFS('Baker BOM'!$B$5:$B$74,A10,'Baker BOM'!$K$5:$K$74,"Listing") -> 9 | E10: =SUMIF('Baker BOM'!$B$5:$B$74,A10,'Baker BOM'!$I$5:$I$74) -> 4891 | F10: =SUMIFS('Baker BOM'!$I$5:$I$74,'Baker BOM'!$B$5:$B$74,A10,'Baker BOM'!$G$5:$G$74,"USD") -> 176 | G10: =F10*Inputs!$B$6 -> 61.6 | H10: =E10+G10 -> 4952.6 | I10: =H10*Inputs!$B$7 -> 742.89 | J10: =H10+I10 -> 5695.49 | K10: =IF($J$15=0,0,J10/$J$15) -> 0.01525232
A11: G | B11: Board handling | C11: =COUNTIF('Baker BOM'!$B$5:$B$74,A11) -> 1 | D11: =COUNTIFS('Baker BOM'!$B$5:$B$74,A11,'Baker BOM'!$K$5:$K$74,"Listing") -> 0 | E11: =SUMIF('Baker BOM'!$B$5:$B$74,A11,'Baker BOM'!$I$5:$I$74) -> 300 | F11: =SUMIFS('Baker BOM'!$I$5:$I$74,'Baker BOM'!$B$5:$B$74,A11,'Baker BOM'!$G$5:$G$74,"USD") -> 0 | G11: =F11*Inputs!$B$6 -> 0 | H11: =E11+G11 -> 300 | I11: =H11*Inputs!$B$7 -> 45 | J11: =H11+I11 -> 345 | K11: =IF($J$15=0,0,J11/$J$15) -> 0.00092389775
A12: H | B12: Electronics & control | C12: =COUNTIF('Baker BOM'!$B$5:$B$74,A12) -> 10 | D12: =COUNTIFS('Baker BOM'!$B$5:$B$74,A12,'Baker BOM'!$K$5:$K$74,"Listing") -> 9 | E12: =SUMIF('Baker BOM'!$B$5:$B$74,A12,'Baker BOM'!$I$5:$I$74) -> 42985 | F12: =SUMIFS('Baker BOM'!$I$5:$I$74,'Baker BOM'!$B$5:$B$74,A12,'Baker BOM'!$G$5:$G$74,"USD") -> 0 | G12: =F12*Inputs!$B$6 -> 0 | H12: =E12+G12 -> 42985 | I12: =H12*Inputs!$B$7 -> 6447.75 | J12: =H12+I12 -> 49432.75 | K12: =IF($J$15=0,0,J12/$J$15) -> 0.13237915
A13: I | B13: Resin printer (high-temp jigs) | C13: =COUNTIF('Baker BOM'!$B$5:$B$74,A13) -> 5 | D13: =COUNTIFS('Baker BOM'!$B$5:$B$74,A13,'Baker BOM'!$K$5:$K$74,"Listing") -> 5 | E13: =SUMIF('Baker BOM'!$B$5:$B$74,A13,'Baker BOM'!$I$5:$I$74) -> 77698 | F13: =SUMIFS('Baker BOM'!$I$5:$I$74,'Baker BOM'!$B$5:$B$74,A13,'Baker BOM'!$G$5:$G$74,"USD") -> 0 | G13: =F13*Inputs!$B$6 -> 0 | H13: =E13+G13 -> 77698 | I13: =H13*Inputs!$B$7 -> 11654.7 | J13: =H13+I13 -> 89352.7 | K13: =IF($J$15=0,0,J13/$J$15) -> 0.23928336
A14: J | B14: First-run consumables | C14: =COUNTIF('Baker BOM'!$B$5:$B$74,A14) -> 5 | D14: =COUNTIFS('Baker BOM'!$B$5:$B$74,A14,'Baker BOM'!$K$5:$K$74,"Listing") -> 3 | E14: =SUMIF('Baker BOM'!$B$5:$B$74,A14,'Baker BOM'!$I$5:$I$74) -> 6280 | F14: =SUMIFS('Baker BOM'!$I$5:$I$74,'Baker BOM'!$B$5:$B$74,A14,'Baker BOM'!$G$5:$G$74,"USD") -> 0 | G14: =F14*Inputs!$B$6 -> 0 | H14: =E14+G14 -> 6280 | I14: =H14*Inputs!$B$7 -> 942 | J14: =H14+I14 -> 7222 | K14: =IF($J$15=0,0,J14/$J$15) -> 0.01934026
B15: Baker prototype total | C15: =SUM(C5:C14) -> 70 | D15: =SUM(D5:D14) -> 58 | E15: =SUM(E5:E14) -> 312464.56 | F15: =SUM(F5:F14) -> 34990.56 | G15: =SUM(G5:G14) -> 12246.696 | H15: =SUM(H5:H14) -> 324711.26 | I15: =SUM(I5:I14) -> 48706.688 | J15: =SUM(J5:J14) -> 373417.94 | K15: =SUM(K5:K14) -> 1
A17: How to read this: "Parts ₹" matches the section totals in the cost report. Duty + courier (35%) applies only to USD-priced (imported) lines. "All-in" spreads duty and the 15% contingency back onto each section, so the all-in column sums to the final prototype cost.

Sheet Baker Production (CN)
A1: Baker — production unit BOM (parts from China, built in Delhi, 100-unit batch)
A2: Design moves vs prototype: ball screws + HGR15 rails; Manta M8P + CB1 replaces Pi 5/Octopus/DM556; one 24 V rail; jig printing on Baker’s own UV engine.
A4: # | B4: Code | C4: Section | D4: Part / description | E4: Qty | F4: Unit price | G4: Cur | H4: Unit ₹ | I4: Line ₹ | J4: Imported? | K4: Price basis | L4: Source (listing seen)
A5: 1 | B5: P1 | C5: Motion | D5: Ball screw SFU1605 set with BK/BF12 ends | E5: 3 | F5: 25 | G5: USD | H5: =IF(G5="USD",F5*Inputs!$B$5,F5) -> 2200 | I5: =E5*H5 -> 6600 | J5: =IF(G5="USD","Yes","No") -> Yes | K5: Listing | L5: ebay.com
A6: 2 | B6: P1 | C6: Motion | D6: HGR15 rail pair + 4 blocks | E6: 3 | F6: 37 | G6: USD | H6: =IF(G6="USD",F6*Inputs!$B$5,F6) -> 3256 | I6: =E6*H6 -> 9768 | J6: =IF(G6="USD","Yes","No") -> Yes | K6: Listing | L6: ebay.com
A7: 3 | B7: P1 | C7: Motion | D7: NEMA23 1.26 Nm, 100+ price | E7: 3 | F7: 11.65 | G7: USD | H7: =IF(G7="USD",F7*Inputs!$B$5,F7) -> 1025.2 | I7: =E7*H7 -> 3075.6 | J7: =IF(G7="USD","Yes","No") -> Yes | K7: Listing | L7: www.omc-stepperonline.com
A8: 4 | B8: P1 | C8: Motion | D8: NEMA17 59 Ncm, 100+ price | E8: 8 | F8: 8.03 | G8: USD | H8: =IF(G8="USD",F8*Inputs!$B$5,F8) -> 706.64 | I8: =E8*H8 -> 5653.12 | J8: =IF(G8="USD","Yes","No") -> Yes | K8: Listing | L8: www.omc-stepperonline.com
A9: 5 | B9: P1 | C9: Motion | D9: Z axes: T8 screw + linear guide, extrusion | E9: 2 | F9: 25 | G9: USD | H9: =IF(G9="USD",F9*Inputs!$B$5,F9) -> 2200 | I9: =E9*H9 -> 4400 | J9: =IF(G9="USD","Yes","No") -> Yes | K9: Estimate
A10: 6 | B10: P2 | C10: Control | D10: BTT Manta M8P V2 (8 drivers, replaces Octopus + DM556) | E10: 1 | F10: 84.38 | G10: USD | H10: =IF(G10="USD",F10*Inputs!$B$5,F10) -> 7425.44 | I10: =E10*H10 -> 7425.44 | J10: =IF(G10="USD","Yes","No") -> Yes | K10: Listing | L10: biqu.equipment
A11: 7 | B11: P2 | C11: Control | D11: BTT CB1 compute module (replaces Pi 5) | E11: 1 | F11: 38.65 | G11: USD | H11: =IF(G11="USD",F11*Inputs!$B$5,F11) -> 3401.2 | I11: =E11*H11 -> 3401.2 | J11: =IF(G11="USD","Yes","No") -> Yes | K11: Listing | L11: www.3djake.com
A12: 8 | B12: P2 | C12: Control | D12: TMC2209 IC on driver sticks, 100+ (chip price) | E12: 8 | F12: 2.07 | G12: USD | H12: =IF(G12="USD",F12*Inputs!$B$5,F12) -> 182.16 | I12: =E12*H12 -> 1457.28 | J12: =IF(G12="USD","Yes","No") -> Yes | K12: Listing | L12: www.lcsc.com
A13: 9 | B13: P2 | C13: Control | D13: BTT HDMI7 touch screen | E13: 1 | F13: 72.58 | G13: USD | H13: =IF(G13="USD",F13*Inputs!$B$5,F13) -> 6387.04 | I13: =E13*H13 -> 6387.04 | J13: =IF(G13="USD","Yes","No") -> Yes | K13: Listing | L13: biqu.equipment
A14: 10 | B14: P2 | C14: Control | D14: Mean Well LRS-350-24, 100+ price (single 24 V rail) | E14: 1 | F14: 17.56 | G14: USD | H14: =IF(G14="USD",F14*Inputs!$B$5,F14) -> 1545.28 | I14: =E14*H14 -> 1545.28 | J14: =IF(G14="USD","Yes","No") -> Yes | K14: Listing | L14: www.omc-stepperonline.com
A15: 11 | B15: P3 | C15: Heads | D15: 500 W ER11 spindle kit (retail; volume lower) | E15: 1 | F15: 85.99 | G15: USD | H15: =IF(G15="USD",F15*Inputs!$B$5,F15) -> 7567.12 | I15: =E15*H15 -> 7567.12 | J15: =IF(G15="USD","Yes","No") -> Yes | K15: Listing | L15: m.banggood.in
A16: 12 | B16: P3 | C16: Heads | D16: 10 W diode laser, LaserTree (retail; volume lower) | E16: 1 | F16: 159 | G16: USD | H16: =IF(G16="USD",F16*Inputs!$B$5,F16) -> 13992 | I16: =E16*H16 -> 13992 | J16: =IF(G16="USD","Yes","No") -> Yes | K16: Listing | L16: lasertree.com
A17: 13 | B17: P4 | C17: Zone B | D17: 10.1 in 12K mono LCD (ChiTu store) | E17: 1 | F17: 110.99 | G17: USD | H17: =IF(G17="USD",F17*Inputs!$B$5,F17) -> 9767.12 | I17: =E17*H17 -> 9767.12 | J17: =IF(G17="USD","Yes","No") -> Yes | K17: Listing | L17: www.chitusystems.com
A18: 14 | B18: P4 | C18: Zone B | D18: ChiTu L K1 LCD board | E18: 1 | F18: 56.68 | G18: USD | H18: =IF(G18="USD",F18*Inputs!$B$5,F18) -> 4987.84 | I18: =E18*H18 -> 4987.84 | J18: =IF(G18="USD","Yes","No") -> Yes | K18: Listing | L18: www.chitusystems.com
A19: 15 | B19: P4 | C19: Zone B | D19: 405 nm parallel UV board 10.1 in | E19: 1 | F19: 40 | G19: USD | H19: =IF(G19="USD",F19*Inputs!$B$5,F19) -> 3520 | I19: =E19*H19 -> 3520 | J19: =IF(G19="USD","Yes","No") -> Yes | K19: Estimate | L19: www.alibaba.com
A20: 16 | B20: P4 | C20: Zone B | D20: Jig-printing vat + lift on the same UV engine (replaces separate printer) | E20: 1 | F20: 3000 | G20: INR | H20: =IF(G20="USD",F20*Inputs!$B$5,F20) -> 3000 | I20: =E20*H20 -> 3000 | J20: =IF(G20="USD","Yes","No") -> No | K20: Estimate
A21: 17 | B21: P5 | C21: Small parts (India) | D21: Pumps, valves, magnets, heater pad, SSR, sensors, fans | E21: 1 | F21: 7500 | G21: INR | H21: =IF(G21="USD",F21*Inputs!$B$5,F21) -> 7500 | I21: =E21*H21 -> 7500 | J21: =IF(G21="USD","Yes","No") -> No | K21: Listing | L21: see prototype sheet
A22: 18 | B22: P6 | C22: Enclosure | D22: Sheet-metal frame + acrylic panels, India fabrication | E22: 1 | F22: 12000 | G22: INR | H22: =IF(G22="USD",F22*Inputs!$B$5,F22) -> 12000 | I22: =E22*H22 -> 12000 | J22: =IF(G22="USD","Yes","No") -> No | K22: Estimate
A23: 19 | B23: P6 | C23: Enclosure | D23: Wiring harness, connectors | E23: 1 | F23: 2500 | G23: INR | H23: =IF(G23="USD",F23*Inputs!$B$5,F23) -> 2500 | I23: =E23*H23 -> 2500 | J23: =IF(G23="USD","Yes","No") -> No | K23: Estimate
D25: Parts total | I25: =SUM(I5:I23) -> 114547.04
D26: of which imported (USD-priced lines) | I26: =SUMIF(G5:G23,"USD",I5:I23) -> 89547.04
D27: Lines priced from a live listing | I27: =COUNTIF(K5:K23,"Listing")&" of "&COUNTA(D5:D23) -> 14 of 19
A29: Baker production unit: cost build-up
D30: Cost line | I30: ₹ / unit | J30: % of unit | K30: Note
D31: P1 Motion | I31: =SUMIF($B$5:$B$23,"P1",$I$5:$I$23) -> 29496.72 | J31: =IF($I$40=0,0,I31/$I$40) -> 0.20364714 | K31: Parts (sum of BOM lines above)
D32: P2 Control | I32: =SUMIF($B$5:$B$23,"P2",$I$5:$I$23) -> 20216.24 | J32: =IF($I$40=0,0,I32/$I$40) -> 0.13957414 | K32: Parts (sum of BOM lines above)
D33: P3 Heads | I33: =SUMIF($B$5:$B$23,"P3",$I$5:$I$23) -> 21559.12 | J33: =IF($I$40=0,0,I33/$I$40) -> 0.14884547 | K33: Parts (sum of BOM lines above)
D34: P4 Zone B | I34: =SUMIF($B$5:$B$23,"P4",$I$5:$I$23) -> 21274.96 | J34: =IF($I$40=0,0,I34/$I$40) -> 0.14688361 | K34: Parts (sum of BOM lines above)
D35: P5 Small parts (India) | I35: =SUMIF($B$5:$B$23,"P5",$I$5:$I$23) -> 7500 | J35: =IF($I$40=0,0,I35/$I$40) -> 0.051780453 | K35: Parts (sum of BOM lines above)
D36: P6 Enclosure | I36: =SUMIF($B$5:$B$23,"P6",$I$5:$I$23) -> 14500 | J36: =IF($I$40=0,0,I36/$I$40) -> 0.10010888 | K36: Parts (sum of BOM lines above)
D37: Duty on China parts (BCD 15% + SWS; IGST credited) | I37: =SUMIF($G$5:$G$23,"USD",$I$5:$I$23)*Inputs!$B$8 -> 14775.262 | J37: =IF($I$40=0,0,I37/$I$40) -> 0.1020093 | K37: Applied to USD-priced (imported) lines only
D38: Sea-freight share (LCL all-in) | I38: =Inputs!$B$9 -> 3520 | J38: =IF($I$40=0,0,I38/$I$40) -> 0.024302293 | K38: From Inputs
D39: Assembly + QC in India | I39: =Inputs!$B$11 -> 12000 | J39: =IF($I$40=0,0,I39/$I$40) -> 0.082848725 | K39: From Inputs (deck figure)
D40: Baker production unit (landed Delhi, 100-unit batch) | I40: =SUM(I31:I39) -> 144842.3 | J40: =IF($I$40=0,0,I40/$I$40) -> 1

Sheet Baker Final Cost
A1: Baker — final prototype cost and production unit cost
A2: Everything on this sheet is a formula linked to the BOM, breakup and Inputs sheets.
A4: A. Final prototype cost (one unit, bought in India)
A5: Step | B5: Amount ₹ | C5: How it is calculated
A6: Parts (all BOM lines) | B6: ='Baker Cost Breakup'!E15 -> 312464.56 | C6: Sum of every line in the prototype BOM
A7: + Duty + courier on imported items | B7: ='Baker Cost Breakup'!G15 -> 12246.696 | C7: 35% × USD-priced lines (see Inputs)
A8: → Subtotal | B8: =B6+B7 -> 324711.26
A9: + Contingency | B9: =B8*Inputs!$B$7 -> 48706.688 | C9: 15% × subtotal (see Inputs)
A10: → FINAL BAKER PROTOTYPE COST | B10: =B8+B9 -> 373417.94 | C10: Matches the cost report
A11: Check: equals sum of all-in section costs on the breakup sheet | B11: =IF(ABS(B10-'Baker Cost Breakup'!J15)<1,"OK","MISMATCH") -> OK
A12: BOM lines priced from a live listing | B12: =COUNTIF('Baker BOM'!K5:K74,"Listing")&" of "&COUNTA('Baker BOM'!D5:D74) -> 58 of 70
A14: B. Production unit and target
A15: Measure | B15: Amount ₹ | C15: Note
A16: Prototype (India, one unit) | B16: =B10 -> 373417.94 | C16: Section A above
A17: Production unit (China parts, Delhi assembly, batch of 100) | B17: ='Baker Production (CN)'!I40 -> 144842.3 | C17: From production sheet
A18: Deck hardware target | B18: =Inputs!$B$13 -> 150000 | C18: From Inputs
A19: Headroom: target − production unit | B19: =B18-B17 -> 5157.6984 | C19: Positive = under target
A20: Production unit as % of target | B20: =IF(B18=0,0,B17/B18) -> 0.96561534
A21: Saving: prototype → production | B21: =B16-B17 -> 228575.64
A22: Saving as % of prototype | B22: =IF(B16=0,0,B21/B16) -> 0.61211746
A23: Risk-adjusted production unit (+ risk allowance) | B23: =B17*(1+Inputs!$B$16) -> 159326.53 | C23: Optional view; allowance is an assumption on Inputs
A24: Risk-adjusted headroom vs target | B24: =B18-B23 -> -9326.5318 | C24: If negative, the target is at risk

Sheet Mixer BOM
A1: Mixer — prototype bill of materials (India-sourced)
A2: 8 instruments on one host: 2-ch scope (12-bit, 65 MS/s), 2-ch wavegen (14-bit), 16-ch logic analyser, pattern generator, protocol decoder, 2 programmable supplies, 24-bit multimeter.
A4: # | B4: Code | C4: Section | D4: Part / description | E4: Qty | F4: Unit price | G4: Cur | H4: Unit ₹ | I4: Line ₹ | J4: Imported? | K4: Price basis | L4: Source (listing seen)
A5: 1 | B5: M1 | C5: Capture and generation | D5: Sipeed Tang Primer 20K Dock (FPGA) | E5: 1 | F5: 9499 | G5: INR | H5: =IF(G5="USD",F5*Inputs!$B$5,F5) -> 9499 | I5: =E5*H5 -> 9499 | J5: =IF(G5="USD","Yes","No") -> No | K5: Listing | L5: probots.co.in
A6: 2 | B6: M1 | C6: Capture and generation | D6: AD9226 12-bit 65 MS/s ADC module (one per channel) | E6: 2 | F6: 26.2 | G6: USD | H6: =IF(G6="USD",F6*Inputs!$B$5,F6) -> 2305.6 | I6: =E6*H6 -> 4611.2 | J6: =IF(G6="USD","Yes","No") -> Yes | K6: Listing | L6: www.ebay.com
A7: 3 | B7: M1 | C7: Capture and generation | D7: AN9767 dual 14-bit 125 MS/s DAC module | E7: 1 | F7: 4088 | G7: INR | H7: =IF(G7="USD",F7*Inputs!$B$5,F7) -> 4088 | I7: =E7*H7 -> 4088 | J7: =IF(G7="USD","Yes","No") -> No | K7: Listing | L7: www.aliexpress.com
A8: 4 | B8: M2 | C8: Front end and instruments | D8: AD8066 dual FET op-amp (input buffers) | E8: 4 | F8: 9 | G8: USD | H8: =IF(G8="USD",F8*Inputs!$B$5,F8) -> 792 | I8: =E8*H8 -> 3168 | J8: =IF(G8="USD","Yes","No") -> Yes | K8: Listing | L8: www.findchips.com
A9: 5 | B9: M2 | C9: Front end and instruments | D9: REF5025 precision reference | E9: 2 | F9: 0.94 | G9: USD | H9: =IF(G9="USD",F9*Inputs!$B$5,F9) -> 82.72 | I9: =E9*H9 -> 165.44 | J9: =IF(G9="USD","Yes","No") -> Yes | K9: Listing | L9: www.lcsc.com
A10: 6 | B10: M2 | C10: Front end and instruments | D10: ADS1256 24-bit ADC module (multimeter) | E10: 1 | F10: 1349 | G10: INR | H10: =IF(G10="USD",F10*Inputs!$B$5,F10) -> 1349 | I10: =E10*H10 -> 1349 | J10: =IF(G10="USD","Yes","No") -> No | K10: Listing | L10: robu.in
A11: 7 | B11: M2 | C11: Front end and instruments | D11: MCP4728 quad DAC (supply setpoints) | E11: 1 | F11: 779 | G11: INR | H11: =IF(G11="USD",F11*Inputs!$B$5,F11) -> 779 | I11: =E11*H11 -> 779 | J11: =IF(G11="USD","Yes","No") -> No | K11: Listing | L11: robu.in
A12: 8 | B12: M2 | C12: Front end and instruments | D12: INA226 power monitor | E12: 2 | F12: 529 | G12: INR | H12: =IF(G12="USD",F12*Inputs!$B$5,F12) -> 529 | I12: =E12*H12 -> 1058 | J12: =IF(G12="USD","Yes","No") -> No | K12: Listing | L12: probots.co.in
A13: 9 | B13: M2 | C13: Front end and instruments | D13: XL6009 buck-boost (programmable supplies) | E13: 2 | F13: 229 | G13: INR | H13: =IF(G13="USD",F13*Inputs!$B$5,F13) -> 229 | I13: =E13*H13 -> 458 | J13: =IF(G13="USD","Yes","No") -> No | K13: Listing | L13: robu.in
A14: 10 | B14: M2 | C14: Front end and instruments | D14: 5 V DPDT signal relay (range switching) | E14: 8 | F14: 49 | G14: INR | H14: =IF(G14="USD",F14*Inputs!$B$5,F14) -> 49 | I14: =E14*H14 -> 392 | J14: =IF(G14="USD","Yes","No") -> No | K14: Listing | L14: probots.co.in
A15: 11 | B15: M2 | C15: Front end and instruments | D15: 74LVC245 level shifter (16-ch logic) | E15: 2 | F15: 1.49 | G15: USD | H15: =IF(G15="USD",F15*Inputs!$B$5,F15) -> 131.12 | I15: =E15*H15 -> 262.24 | J15: =IF(G15="USD","Yes","No") -> Yes | K15: Listing | L15: tinkersphere.com
A16: 12 | B16: M2 | C16: Front end and instruments | D16: 0805 resistor sample book, 8500 pcs | E16: 1 | F16: 2520 | G16: INR | H16: =IF(G16="USD",F16*Inputs!$B$5,F16) -> 2520 | I16: =E16*H16 -> 2520 | J16: =IF(G16="USD","Yes","No") -> No | K16: Listing | L16: rajivelectronics.com
... A27: 23 | B27: M3 | C27: Host, screen, I/O | D27: 12 V 5 A adapter | E27: 1 | F27: 425 | G27: INR | H27: =IF(G27="USD",F27*Inputs!$B$5,F27) -> 425 | I27: =E27*H27 -> 425 | J27: =IF(G27="USD","Yes","No") -> No | K27: Listing | L27: robu.in
A28: 24 | B28: M4 | C28: Enclosure | D28: Vacuum-formed shell (HIPS sheet, in-house former) | E28: 1 | F28: 800 | G28: INR | H28: =IF(G28="USD",F28*Inputs!$B$5,F28) -> 800 | I28: =E28*H28 -> 800 | J28: =IF(G28="USD","Yes","No") -> No | K28: Estimate
A29: 25 | B29: M4 | C29: Enclosure | D29: Acrylic front panel (laser-cut) | E29: 1 | F29: 310 | G29: INR | H29: =IF(G29="USD",F29*Inputs!$B$5,F29) -> 310 | I29: =E29*H29 -> 310 | J29: =IF(G29="USD","Yes","No") -> No | K29: Listing | L29: www.acrylicsheetsindia.com
A30: 26 | B30: M4 | C30: Enclosure | D30: Fan, fasteners, wiring | E30: 1 | F30: 400 | G30: INR | H30: =IF(G30="USD",F30*Inputs!$B$5,F30) -> 400 | I30: =E30*H30 -> 400 | J30: =IF(G30="USD","Yes","No") -> No | K30: Estimate
D32: Parts total | I32: =SUM(I5:I30) -> 62211.88
D33: of which imported (USD-priced lines) | I33: =SUMIF(G5:G30,"USD",I5:I30) -> 8206.88
D34: Lines priced from a live listing | I34: =COUNTIF(K5:K30,"Listing")&" of "&COUNTA(D5:D30) -> 23 of 26

Sheet Mixer Cost Breakup
A1: Mixer — prototype cost breakup by section
A2: Section totals from the Mixer BOM, then duty/courier and contingency.
A4: Code | B4: Section | C4: BOM lines | D4: Listing-priced | E4: Parts ₹ | F4: of which imported ₹ | G4: Duty + courier ₹ | H4: Subtotal ₹ | I4: Contingency ₹ | J4: All-in section cost ₹ | K4: % of total
A5: M1 | B5: Capture and generation | C5: =COUNTIF('Mixer BOM'!$B$5:$B$30,A5) -> 3 | D5: =COUNTIFS('Mixer BOM'!$B$5:$B$30,A5,'Mixer BOM'!$K$5:$K$30,"Listing") -> 3 | E5: =SUMIF('Mixer BOM'!$B$5:$B$30,A5,'Mixer BOM'!$I$5:$I$30) -> 18198.2 | F5: =SUMIFS('Mixer BOM'!$I$5:$I$30,'Mixer BOM'!$B$5:$B$30,A5,'Mixer BOM'!$G$5:$G$30,"USD") -> 4611.2 | G5: =F5*Inputs!$B$6 -> 1613.92 | H5: =E5+G5 -> 19812.12 | I5: =H5*Inputs!$B$7 -> 2971.818 | J5: =H5+I5 -> 22783.938 | K5: =IF($J$9=0,0,J5/$J$9) -> 0.30440711
A6: M2 | B6: Front end and instruments | C6: =COUNTIF('Mixer BOM'!$B$5:$B$30,A6) -> 11 | D6: =COUNTIFS('Mixer BOM'!$B$5:$B$30,A6,'Mixer BOM'!$K$5:$K$30,"Listing") -> 10 | E6: =SUMIF('Mixer BOM'!$B$5:$B$30,A6,'Mixer BOM'!$I$5:$I$30) -> 15751.68 | F6: =SUMIFS('Mixer BOM'!$I$5:$I$30,'Mixer BOM'!$B$5:$B$30,A6,'Mixer BOM'!$G$5:$G$30,"USD") -> 3595.68 | G6: =F6*Inputs!$B$6 -> 1258.488 | H6: =E6+G6 -> 17010.168 | I6: =H6*Inputs!$B$7 -> 2551.5252 | J6: =H6+I6 -> 19561.693 | K6: =IF($J$9=0,0,J6/$J$9) -> 0.26135598
A7: M3 | B7: Host, screen, I/O | C7: =COUNTIF('Mixer BOM'!$B$5:$B$30,A7) -> 9 | D7: =COUNTIFS('Mixer BOM'!$B$5:$B$30,A7,'Mixer BOM'!$K$5:$K$30,"Listing") -> 9 | E7: =SUMIF('Mixer BOM'!$B$5:$B$30,A7,'Mixer BOM'!$I$5:$I$30) -> 26752 | F7: =SUMIFS('Mixer BOM'!$I$5:$I$30,'Mixer BOM'!$B$5:$B$30,A7,'Mixer BOM'!$G$5:$G$30,"USD") -> 0 | G7: =F7*Inputs!$B$6 -> 0 | H7: =E7+G7 -> 26752 | I7: =H7*Inputs!$B$7 -> 4012.8 | J7: =H7+I7 -> 30764.8 | K7: =IF($J$9=0,0,J7/$J$9) -> 0.41103622
A8: M4 | B8: Enclosure | C8: =COUNTIF('Mixer BOM'!$B$5:$B$30,A8) -> 3 | D8: =COUNTIFS('Mixer BOM'!$B$5:$B$30,A8,'Mixer BOM'!$K$5:$K$30,"Listing") -> 1 | E8: =SUMIF('Mixer BOM'!$B$5:$B$30,A8,'Mixer BOM'!$I$5:$I$30) -> 1510 | F8: =SUMIFS('Mixer BOM'!$I$5:$I$30,'Mixer BOM'!$B$5:$B$30,A8,'Mixer BOM'!$G$5:$G$30,"USD") -> 0 | G8: =F8*Inputs!$B$6 -> 0 | H8: =E8+G8 -> 1510 | I8: =H8*Inputs!$B$7 -> 226.5 | J8: =H8+I8 -> 1736.5 | K8: =IF($J$9=0,0,J8/$J$9) -> 0.023200684
B9: Mixer prototype total | C9: =SUM(C5:C8) -> 26 | D9: =SUM(D5:D8) -> 23 | E9: =SUM(E5:E8) -> 62211.88 | F9: =SUM(F5:F8) -> 8206.88 | G9: =SUM(G5:G8) -> 2872.408 | H9: =SUM(H5:H8) -> 65084.288 | I9: =SUM(I5:I8) -> 9762.6432 | J9: =SUM(J5:J8) -> 74846.931 | K9: =SUM(K5:K8) -> 1
A11: How to read this: "Parts ₹" matches the section totals in the cost report. Duty + courier (35%) applies only to USD-priced (imported) lines. "All-in" spreads duty and the 15% contingency back onto each section, so the all-in column sums to the final prototype cost.

Sheet Mixer Production (CN)
A1: Mixer — production unit BOM (parts from China, built in Delhi, 100-unit batch)
A2: Production Mixer drops to 8-bit capture/generation (AD9288, DAC908) and one USB cable with no screen: the trade that gets it under ₹15,000.
A4: # | B4: Code | C4: Section | D4: Part / description | E4: Qty | F4: Unit price | G4: Cur | H4: Unit ₹ | I4: Line ₹ | J4: Imported? | K4: Price basis | L4: Source (listing seen)
A5: 1 | B5: Q1 | C5: Silicon | D5: Tang Nano 9K FPGA module (GW1NR-9 + 64 Mb PSRAM) | E5: 1 | F5: 20 | G5: USD | H5: =IF(G5="USD",F5*Inputs!$B$5,F5) -> 1760 | I5: =E5*H5 -> 1760 | J5: =IF(G5="USD","Yes","No") -> Yes | K5: Listing | L5: store.lushaylabs.com
A6: 2 | B6: Q1 | C6: Silicon | D6: AD9288 dual 8-bit 80 MS/s ADC, 100+ | E6: 1 | F6: 6.7 | G6: USD | H6: =IF(G6="USD",F6*Inputs!$B$5,F6) -> 589.6 | I6: =E6*H6 -> 589.6 | J6: =IF(G6="USD","Yes","No") -> Yes | K6: Listing | L6: www.lcsc.com
A7: 3 | B7: Q1 | C7: Silicon | D7: DAC908 8-bit 165 MS/s DAC, 100+ | E7: 2 | F7: 5.2 | G7: USD | H7: =IF(G7="USD",F7*Inputs!$B$5,F7) -> 457.6 | I7: =E7*H7 -> 915.2 | J7: =IF(G7="USD","Yes","No") -> Yes | K7: Listing | L7: www.lcsc.com
A8: 4 | B8: Q1 | C8: Silicon | D8: FT232HL USB 2.0 high-speed bridge, 100+ | E8: 1 | F8: 6.36 | G8: USD | H8: =IF(G8="USD",F8*Inputs!$B$5,F8) -> 559.68 | I8: =E8*H8 -> 559.68 | J8: =IF(G8="USD","Yes","No") -> Yes | K8: Listing | L8: www.lcsc.com
A9: 5 | B9: Q1 | C9: Silicon | D9: ADS1256 24-bit ADC (multimeter), 100+ | E9: 1 | F9: 4.53 | G9: USD | H9: =IF(G9="USD",F9*Inputs!$B$5,F9) -> 398.64 | I9: =E9*H9 -> 398.64 | J9: =IF(G9="USD","Yes","No") -> Yes | K9: Listing | L9: www.lcsc.com
A10: 6 | B10: Q1 | C10: Silicon | D10: AD8066 dual op-amp, 100+ | E10: 4 | F10: 7.06 | G10: USD | H10: =IF(G10="USD",F10*Inputs!$B$5,F10) -> 621.28 | I10: =E10*H10 -> 2485.12 | J10: =IF(G10="USD","Yes","No") -> Yes | K10: Listing | L10: www.lcsc.com
A11: 7 | B11: Q1 | C11: Silicon | D11: REF5025 reference, 100+ | E11: 1 | F11: 0.57 | G11: USD | H11: =IF(G11="USD",F11*Inputs!$B$5,F11) -> 50.16 | I11: =E11*H11 -> 50.16 | J11: =IF(G11="USD","Yes","No") -> Yes | K11: Listing | L11: www.lcsc.com
A12: 8 | B12: Q2 | C12: Board | D12: Supply DACs, INA226, relays, protection, passives | E12: 1 | F12: 12 | G12: USD | H12: =IF(G12="USD",F12*Inputs!$B$5,F12) -> 1056 | I12: =E12*H12 -> 1056 | J12: =IF(G12="USD","Yes","No") -> Yes | K12: Estimate
A13: 9 | B13: Q2 | C13: Board | D13: 4-layer PCB + JLCPCB assembly share at 100 pcs | E13: 1 | F13: 8 | G13: USD | H13: =IF(G13="USD",F13*Inputs!$B$5,F13) -> 704 | I13: =E13*H13 -> 704 | J13: =IF(G13="USD","Yes","No") -> Yes | K13: Listing | L13: jlcpcb.com
A14: 10 | B14: Q2 | C14: Board | D14: BNC, banana jacks, USB-C, logic header | E14: 1 | F14: 4 | G14: USD | H14: =IF(G14="USD",F14*Inputs!$B$5,F14) -> 352 | I14: =E14*H14 -> 352 | J14: =IF(G14="USD","Yes","No") -> Yes | K14: Estimate
A15: 11 | B15: Q3 | C15: Enclosure | D15: Extruded aluminium case with end panels | E15: 1 | F15: 6 | G15: USD | H15: =IF(G15="USD",F15*Inputs!$B$5,F15) -> 528 | I15: =E15*H15 -> 528 | J15: =IF(G15="USD","Yes","No") -> Yes | K15: Estimate
A16: 12 | B16: Q4 | C16: Accessories | D16: Two 10x probes + USB cable | E16: 1 | F16: 6 | G16: USD | H16: =IF(G16="USD",F16*Inputs!$B$5,F16) -> 528 | I16: =E16*H16 -> 528 | J16: =IF(G16="USD","Yes","No") -> Yes | K16: Estimate
D18: Parts total | I18: =SUM(I5:I16) -> 9926.4
D19: of which imported (USD-priced lines) | I19: =SUMIF(G5:G16,"USD",I5:I16) -> 9926.4
D20: Lines priced from a live listing | I20: =COUNTIF(K5:K16,"Listing")&" of "&COUNTA(D5:D16) -> 8 of 12
A22: Mixer production unit: cost build-up
D23: Cost line | I23: ₹ / unit | J23: % of unit | K23: Note
D24: Q1 Silicon | I24: =SUMIF($B$5:$B$16,"Q1",$I$5:$I$16) -> 6758.4 | J24: =IF($I$31=0,0,I24/$I$31) -> 0.49186856 | K24: Parts (sum of BOM lines above)
D25: Q2 Board | I25: =SUMIF($B$5:$B$16,"Q2",$I$5:$I$16) -> 2112 | J25: =IF($I$31=0,0,I25/$I$31) -> 0.15370893 | K25: Parts (sum of BOM lines above)
D26: Q3 Enclosure | I26: =SUMIF($B$5:$B$16,"Q3",$I$5:$I$16) -> 528 | J26: =IF($I$31=0,0,I26/$I$31) -> 0.038427232 | K26: Parts (sum of BOM lines above)
D27: Q4 Accessories | I27: =SUMIF($B$5:$B$16,"Q4",$I$5:$I$16) -> 528 | J27: =IF($I$31=0,0,I27/$I$31) -> 0.038427232 | K27: Parts (sum of BOM lines above)
D28: Duty on China parts (BCD 15% + SWS; IGST credited) | I28: =SUMIF($G$5:$G$16,"USD",$I$5:$I$16)*Inputs!$B$8 -> 1637.856 | J28: =IF($I$31=0,0,I28/$I$31) -> 0.11920127 | K28: Applied to USD-priced (imported) lines only
D29: Sea-freight share (LCL all-in) | I29: =Inputs!$B$10 -> 176 | J29: =IF($I$31=0,0,I29/$I$31) -> 0.012809077 | K29: From Inputs
D30: Assembly + QC in India | I30: =Inputs!$B$12 -> 2000 | J30: =IF($I$31=0,0,I30/$I$31) -> 0.1455577 | K30: From Inputs (deck figure)
D31: Mixer production unit (landed Delhi, 100-unit batch) | I31: =SUM(I24:I30) -> 13740.256 | J31: =IF($I$31=0,0,I31/$I$31) -> 1

Sheet Mixer Final Cost
A1: Mixer — final prototype cost and production unit cost
A2: Everything on this sheet is a formula linked to the BOM, breakup and Inputs sheets.
A4: A. Final prototype cost (one unit, bought in India)
A5: Step | B5: Amount ₹ | C5: How it is calculated
A6: Parts (all BOM lines) | B6: ='Mixer Cost Breakup'!E9 -> 62211.88 | C6: Sum of every line in the prototype BOM
A7: + Duty + courier on imported items | B7: ='Mixer Cost Breakup'!G9 -> 2872.408 | C7: 35% × USD-priced lines (see Inputs)
A8: → Subtotal | B8: =B6+B7 -> 65084.288
A9: + Contingency | B9: =B8*Inputs!$B$7 -> 9762.6432 | C9: 15% × subtotal (see Inputs)
A10: → FINAL MIXER PROTOTYPE COST | B10: =B8+B9 -> 74846.931 | C10: Matches the cost report
A11: Check: equals sum of all-in section costs on the breakup sheet | B11: =IF(ABS(B10-'Mixer Cost Breakup'!J9)<1,"OK","MISMATCH") -> OK
A12: BOM lines priced from a live listing | B12: =COUNTIF('Mixer BOM'!K5:K30,"Listing")&" of "&COUNTA('Mixer BOM'!D5:D30) -> 23 of 26
A14: B. Production unit and target
A15: Measure | B15: Amount ₹ | C15: Note
A16: Prototype (India, one unit) | B16: =B10 -> 74846.931 | C16: Section A above
A17: Production unit (China parts, Delhi assembly, batch of 100) | B17: ='Mixer Production (CN)'!I31 -> 13740.256 | C17: From production sheet
A18: Deck hardware target | B18: =Inputs!$B$14 -> 15000 | C18: From Inputs
A19: Headroom: target − production unit | B19: =B18-B17 -> 1259.744 | C19: Positive = under target
A20: Production unit as % of target | B20: =IF(B18=0,0,B17/B18) -> 0.91601707
A21: Saving: prototype → production | B21: =B16-B17 -> 61106.675
A22: Saving as % of prototype | B22: =IF(B16=0,0,B21/B16) -> 0.81642192
A23: Risk-adjusted production unit (+ risk allowance) | B23: =B17*(1+Inputs!$B$16) -> 15114.282 | C23: Optional view; allowance is an assumption on Inputs
A24: Risk-adjusted headroom vs target | B24: =B18-B23 -> -114.2816 | C24: If negative, the target is at risk

Sheet Inputs
A1: Inputs & assumptions
A2: Blue cells are inputs: change them and every BOM, cost breakup and final cost updates. Yellow = key assumption.
A4: Input | B4: Value | C4: Unit | D4: Source / note
A5: USD → INR exchange rate | B5: 88 | C5: ₹ per $ | D5: Cost report, 29 Sep 2026 (USD converted at ₹88)
A6: Prototype: duty + courier on imported (USD-priced) items | B6: 0.35 | C6: % | D6: Cost report: imported prototype items carry 35% for duty and courier
A7: Prototype: contingency | B7: 0.15 | C7: % | D7: Cost report: 15% contingency on prototype subtotal
A8: Production: duty on China parts (BCD 15% + SWS) | B8: 0.165 | C8: % | D8: Cost report: HS 8501 rates (EximPe); IGST credited. Confirm with customs broker
A9: Production: sea-freight share per Baker (LCL all-in) | B9: 3520 | C9: ₹/unit | D9: Cost report: Sino-Shipping Sep 2026 rates
A10: Production: sea-freight share per Mixer (LCL all-in) | B10: 176 | C10: ₹/unit | D10: Cost report: Sino-Shipping Sep 2026 rates
A11: Production: Baker assembly + QC in India | B11: 12000 | C11: ₹/unit | D11: Cost report (pitch-deck figure)
A12: Production: Mixer assembly + QC in India | B12: 2000 | C12: ₹/unit | D12: Cost report (pitch-deck figure)
A13: Deck hardware target: Baker | B13: 150000 | C13: ₹/unit | D13: Pitch deck
A14: Deck hardware target: Mixer | B14: 15000 | C14: ₹/unit | D14: Pitch deck
A15: Production batch size | B15: 100 | C15: units | D15: Cost report: China parts bought in batches of 100
A16: Risk allowance on production unit (optional view) | B16: 0.1 | C16: % | D16: ASSUMPTION added in this workbook, not in the cost report. Production figures in the report carry no contingency; this only feeds the "risk-adjusted" line
A19: Colour legend
A20: Blue text = hardcoded input (edit these)
A21: Black text = formula
A22: Green text = pulled from another sheet
